2022-08-26 14:22:51,087 INFO    MainThread:4212 [internal.py:wandb_internal():90] W&B internal server running at pid: 4212, started at: 2022-08-26 14:22:51.083029
2022-08-26 14:22:51,088 INFO    WriterThread:4212 [datastore.py:open_for_write():75] open: D:\fp\ppo_rl\controllers\supervisor_manager\wandb\run-20220826_142250-2f2r95y7\run-2f2r95y7.wandb
2022-08-26 14:22:51,089 DEBUG   SenderThread:4212 [sender.py:send():235] send: header
2022-08-26 14:22:51,089 DEBUG   SenderThread:4212 [sender.py:send():235] send: run
2022-08-26 14:23:01,983 ERROR   SenderThread:4212 [retry.py:__call__():126] Retry attempt failed:
Traceback (most recent call last):
  File "C:\Python38\lib\site-packages\urllib3\connection.py", line 174, in _new_conn
    conn = connection.create_connection(
  File "C:\Python38\lib\site-packages\urllib3\util\connection.py", line 72, in create_connection
    for res in socket.getaddrinfo(host, port, family, socket.SOCK_STREAM):
  File "C:\Python38\lib\socket.py", line 918, in getaddrinfo
    for res in _socket.getaddrinfo(host, port, family, type, proto, flags):
socket.gaierror: [Errno 11001] getaddrinfo failed

During handling of the above exception, another exception occurred:

Traceback (most recent call last):
  File "C:\Python38\lib\site-packages\urllib3\connectionpool.py", line 703, in urlopen
    httplib_response = self._make_request(
  File "C:\Python38\lib\site-packages\urllib3\connectionpool.py", line 386, in _make_request
    self._validate_conn(conn)
  File "C:\Python38\lib\site-packages\urllib3\connectionpool.py", line 1040, in _validate_conn
    conn.connect()
  File "C:\Python38\lib\site-packages\urllib3\connection.py", line 358, in connect
    self.sock = conn = self._new_conn()
  File "C:\Python38\lib\site-packages\urllib3\connection.py", line 186, in _new_conn
    raise NewConnectionError(
urllib3.exceptions.NewConnectionError: <urllib3.connection.HTTPSConnection object at 0x0000028B4AE6B730>: Failed to establish a new connection: [Errno 11001] getaddrinfo failed

During handling of the above exception, another exception occurred:

Traceback (most recent call last):
  File "C:\Python38\lib\site-packages\requests\adapters.py", line 489, in send
    resp = conn.urlopen(
  File "C:\Python38\lib\site-packages\urllib3\connectionpool.py", line 785, in urlopen
    retries = retries.increment(
  File "C:\Python38\lib\site-packages\urllib3\util\retry.py", line 592, in increment
    raise MaxRetryError(_pool, url, error or ResponseError(cause))
urllib3.exceptions.MaxRetryError: HTTPSConnectionPool(host='api.wandb.ai', port=443): Max retries exceeded with url: /graphql (Caused by NewConnectionError('<urllib3.connection.HTTPSConnection object at 0x0000028B4AE6B730>: Failed to establish a new connection: [Errno 11001] getaddrinfo failed'))

During handling of the above exception, another exception occurred:

Traceback (most recent call last):
  File "C:\Python38\lib\site-packages\wandb\sdk\lib\retry.py", line 102, in __call__
    result = self._call_fn(*args, **kwargs)
  File "C:\Python38\lib\site-packages\wandb\sdk\internal\internal_api.py", line 140, in execute
    return self.client.execute(*args, **kwargs)
  File "C:\Python38\lib\site-packages\wandb\vendor\gql-0.2.0\wandb_gql\client.py", line 52, in execute
    result = self._get_result(document, *args, **kwargs)
  File "C:\Python38\lib\site-packages\wandb\vendor\gql-0.2.0\wandb_gql\client.py", line 60, in _get_result
    return self.transport.execute(document, *args, **kwargs)
  File "C:\Python38\lib\site-packages\wandb\vendor\gql-0.2.0\wandb_gql\transport\requests.py", line 38, in execute
    request = requests.post(self.url, **post_args)
  File "C:\Python38\lib\site-packages\requests\api.py", line 115, in post
    return request("post", url, data=data, json=json, **kwargs)
  File "C:\Python38\lib\site-packages\requests\api.py", line 59, in request
    return session.request(method=method, url=url, **kwargs)
  File "C:\Python38\lib\site-packages\requests\sessions.py", line 587, in request
    resp = self.send(prep, **send_kwargs)
  File "C:\Python38\lib\site-packages\requests\sessions.py", line 701, in send
    r = adapter.send(request, **kwargs)
  File "C:\Python38\lib\site-packages\requests\adapters.py", line 565, in send
    raise ConnectionError(e, request=request)
requests.exceptions.ConnectionError: HTTPSConnectionPool(host='api.wandb.ai', port=443): Max retries exceeded with url: /graphql (Caused by NewConnectionError('<urllib3.connection.HTTPSConnection object at 0x0000028B4AE6B730>: Failed to establish a new connection: [Errno 11001] getaddrinfo failed'))
2022-08-26 14:23:20,580 DEBUG   HandlerThread:4212 [handler.py:handle_request():141] handle_request: shutdown
2022-08-26 14:23:20,581 INFO    HandlerThread:4212 [handler.py:finish():806] shutting down handler
2022-08-26 14:23:21,324 INFO    WriterThread:4212 [datastore.py:close():279] close: D:\fp\ppo_rl\controllers\supervisor_manager\wandb\run-20220826_142250-2f2r95y7\run-2f2r95y7.wandb
2022-08-26 14:24:37,030 INFO    SenderThread:4212 [dir_watcher.py:__init__():205] watching files in: D:\fp\ppo_rl\controllers\supervisor_manager\wandb\run-20220826_142250-2f2r95y7\files
2022-08-26 14:24:37,030 INFO    SenderThread:4212 [sender.py:_start_run_threads():812] run started: 2f2r95y7 with start time 1661494970
2022-08-26 14:24:37,030 INFO    SenderThread:4212 [sender.py:finish():1111] shutting down sender
2022-08-26 14:24:37,030 INFO    SenderThread:4212 [dir_watcher.py:finish():336] shutting down directory watcher
2022-08-26 14:24:38,041 INFO    SenderThread:4212 [dir_watcher.py:finish():366] scan: D:\fp\ppo_rl\controllers\supervisor_manager\wandb\run-20220826_142250-2f2r95y7\files
2022-08-26 14:24:38,041 INFO    SenderThread:4212 [dir_watcher.py:finish():380] scan save: D:\fp\ppo_rl\controllers\supervisor_manager\wandb\run-20220826_142250-2f2r95y7\files\config.yaml config.yaml
2022-08-26 14:24:38,041 INFO    SenderThread:4212 [file_pusher.py:finish():145] shutting down file pusher
2022-08-26 14:24:38,041 INFO    SenderThread:4212 [file_pusher.py:join():150] waiting for file pusher
2022-08-26 14:24:48,413 INFO    Thread-13 :4212 [upload_job.py:push():132] Uploaded file D:\fp\ppo_rl\controllers\supervisor_manager\wandb\run-20220826_142250-2f2r95y7\files\config.yaml
2022-08-26 14:24:50,148 INFO    MainThread:4212 [internal.py:handle_exit():80] Internal process exited
