2022-08-27 17:52:50,986 INFO    MainThread:2940 [wandb_setup.py:_flush():76] Loading settings from C:\Users\002\.config\wandb\settings
2022-08-27 17:52:50,986 INFO    MainThread:2940 [wandb_setup.py:_flush():76] Loading settings from D:\fp\ppo_rl\controllers\supervisor_manager\wandb\settings
2022-08-27 17:52:50,986 INFO    MainThread:2940 [wandb_setup.py:_flush():76] Loading settings from environment variables: {}
2022-08-27 17:52:50,986 INFO    MainThread:2940 [wandb_setup.py:_flush():76] Inferring run settings from compute environment: {'program_relpath': 'supervisor_manager.py', 'program': 'supervisor_manager.py'}
2022-08-27 17:52:50,986 INFO    MainThread:2940 [wandb_init.py:_log_setup():428] Logging user logs to D:\fp\ppo_rl\controllers\supervisor_manager\wandb\run-20220827_175250-1l9e6q42\logs\debug.log
2022-08-27 17:52:50,986 INFO    MainThread:2940 [wandb_init.py:_log_setup():429] Logging internal logs to D:\fp\ppo_rl\controllers\supervisor_manager\wandb\run-20220827_175250-1l9e6q42\logs\debug-internal.log
2022-08-27 17:52:50,987 INFO    MainThread:2940 [wandb_init.py:init():462] calling init triggers
2022-08-27 17:52:50,987 INFO    MainThread:2940 [wandb_init.py:init():465] wandb.init called with sweep_config: {}
config: {}
2022-08-27 17:52:50,987 INFO    MainThread:2940 [wandb_init.py:init():515] starting backend
2022-08-27 17:52:50,987 INFO    MainThread:2940 [backend.py:_multiprocessing_setup():97] multiprocessing start_methods=spawn, using: spawn
2022-08-27 17:52:50,990 INFO    MainThread:2940 [backend.py:ensure_launched():217] starting backend process...
2022-08-27 17:52:51,031 INFO    MainThread:2940 [backend.py:ensure_launched():222] started backend process with pid: 5540
2022-08-27 17:52:51,031 INFO    MainThread:2940 [wandb_init.py:init():525] backend started and connected
2022-08-27 17:52:51,033 INFO    MainThread:2940 [wandb_init.py:init():596] updated telemetry
2022-08-27 17:52:51,034 INFO    MainThread:2940 [wandb_init.py:init():627] communicating run to backend with 30 second timeout
2022-08-27 17:53:19,511 ERROR   Thread-5  :2940 [retry.py:__call__():126] Retry attempt failed:
Traceback (most recent call last):
  File "C:\Python38\lib\site-packages\urllib3\connection.py", line 174, in _new_conn
    conn = connection.create_connection(
  File "C:\Python38\lib\site-packages\urllib3\util\connection.py", line 95, in create_connection
    raise err
  File "C:\Python38\lib\site-packages\urllib3\util\connection.py", line 85, in create_connection
    sock.connect(sa)
socket.timeout: timed out

During handling of the above exception, another exception occurred:

Traceback (most recent call last):
  File "C:\Python38\lib\site-packages\urllib3\connectionpool.py", line 703, in urlopen
    httplib_response = self._make_request(
  File "C:\Python38\lib\site-packages\urllib3\connectionpool.py", line 386, in _make_request
    self._validate_conn(conn)
  File "C:\Python38\lib\site-packages\urllib3\connectionpool.py", line 1040, in _validate_conn
    conn.connect()
  File "C:\Python38\lib\site-packages\urllib3\connection.py", line 358, in connect
    self.sock = conn = self._new_conn()
  File "C:\Python38\lib\site-packages\urllib3\connection.py", line 179, in _new_conn
    raise ConnectTimeoutError(
urllib3.exceptions.ConnectTimeoutError: (<urllib3.connection.HTTPSConnection object at 0x000001625219F1F0>, 'Connection to api.wandb.ai timed out. (connect timeout=10)')

During handling of the above exception, another exception occurred:

Traceback (most recent call last):
  File "C:\Python38\lib\site-packages\requests\adapters.py", line 489, in send
    resp = conn.urlopen(
  File "C:\Python38\lib\site-packages\urllib3\connectionpool.py", line 785, in urlopen
    retries = retries.increment(
  File "C:\Python38\lib\site-packages\urllib3\util\retry.py", line 592, in increment
    raise MaxRetryError(_pool, url, error or ResponseError(cause))
urllib3.exceptions.MaxRetryError: HTTPSConnectionPool(host='api.wandb.ai', port=443): Max retries exceeded with url: /graphql (Caused by ConnectTimeoutError(<urllib3.connection.HTTPSConnection object at 0x000001625219F1F0>, 'Connection to api.wandb.ai timed out. (connect timeout=10)'))

During handling of the above exception, another exception occurred:

Traceback (most recent call last):
  File "C:\Python38\lib\site-packages\wandb\sdk\lib\retry.py", line 102, in __call__
    result = self._call_fn(*args, **kwargs)
  File "C:\Python38\lib\site-packages\wandb\sdk\internal\internal_api.py", line 140, in execute
    return self.client.execute(*args, **kwargs)
  File "C:\Python38\lib\site-packages\wandb\vendor\gql-0.2.0\wandb_gql\client.py", line 52, in execute
    result = self._get_result(document, *args, **kwargs)
  File "C:\Python38\lib\site-packages\wandb\vendor\gql-0.2.0\wandb_gql\client.py", line 60, in _get_result
    return self.transport.execute(document, *args, **kwargs)
  File "C:\Python38\lib\site-packages\wandb\vendor\gql-0.2.0\wandb_gql\transport\requests.py", line 38, in execute
    request = requests.post(self.url, **post_args)
  File "C:\Python38\lib\site-packages\requests\api.py", line 115, in post
    return request("post", url, data=data, json=json, **kwargs)
  File "C:\Python38\lib\site-packages\requests\api.py", line 59, in request
    return session.request(method=method, url=url, **kwargs)
  File "C:\Python38\lib\site-packages\requests\sessions.py", line 587, in request
    resp = self.send(prep, **send_kwargs)
  File "C:\Python38\lib\site-packages\requests\sessions.py", line 701, in send
    r = adapter.send(request, **kwargs)
  File "C:\Python38\lib\site-packages\requests\adapters.py", line 553, in send
    raise ConnectTimeout(e, request=request)
requests.exceptions.ConnectTimeout: HTTPSConnectionPool(host='api.wandb.ai', port=443): Max retries exceeded with url: /graphql (Caused by ConnectTimeoutError(<urllib3.connection.HTTPSConnection object at 0x000001625219F1F0>, 'Connection to api.wandb.ai timed out. (connect timeout=10)'))
2022-08-27 17:53:21,043 INFO    MainThread:2940 [interface_shared.py:_communicate_run():326] couldn't get run from backend
2022-08-27 17:53:21,043 ERROR   MainThread:2940 [wandb_init.py:init():636] backend process timed out
2022-08-27 17:53:21,043 ERROR   MainThread:2940 [wandb_init.py:init():647] encountered error: Error communicating with wandb process
try: wandb.init(settings=wandb.Settings(start_method='fork'))
or:  wandb.init(settings=wandb.Settings(start_method='thread'))
For more info see: https://docs.wandb.ai/library/init#init-start-error
