2022-08-26 14:22:50,506 INFO    MainThread:12236 [wandb_setup.py:_flush():76] Loading settings from C:\Users\002\.config\wandb\settings
2022-08-26 14:22:50,506 INFO    MainThread:12236 [wandb_setup.py:_flush():76] Loading settings from D:\fp\ppo_rl\controllers\supervisor_manager\wandb\settings
2022-08-26 14:22:50,506 INFO    MainThread:12236 [wandb_setup.py:_flush():76] Loading settings from environment variables: {}
2022-08-26 14:22:50,506 INFO    MainThread:12236 [wandb_setup.py:_flush():76] Inferring run settings from compute environment: {'program_relpath': 'supervisor_manager.py', 'program': 'supervisor_manager.py'}
2022-08-26 14:22:50,506 INFO    MainThread:12236 [wandb_init.py:_log_setup():428] Logging user logs to D:\fp\ppo_rl\controllers\supervisor_manager\wandb\run-20220826_142250-2f2r95y7\logs\debug.log
2022-08-26 14:22:50,506 INFO    MainThread:12236 [wandb_init.py:_log_setup():429] Logging internal logs to D:\fp\ppo_rl\controllers\supervisor_manager\wandb\run-20220826_142250-2f2r95y7\logs\debug-internal.log
2022-08-26 14:22:50,507 INFO    MainThread:12236 [wandb_init.py:init():462] calling init triggers
2022-08-26 14:22:50,507 INFO    MainThread:12236 [wandb_init.py:init():465] wandb.init called with sweep_config: {}
config: {}
2022-08-26 14:22:50,507 INFO    MainThread:12236 [wandb_init.py:init():515] starting backend
2022-08-26 14:22:50,507 INFO    MainThread:12236 [backend.py:_multiprocessing_setup():97] multiprocessing start_methods=spawn, using: spawn
2022-08-26 14:22:50,518 INFO    MainThread:12236 [backend.py:ensure_launched():217] starting backend process...
2022-08-26 14:22:50,562 INFO    MainThread:12236 [backend.py:ensure_launched():222] started backend process with pid: 4212
2022-08-26 14:22:50,562 INFO    MainThread:12236 [wandb_init.py:init():525] backend started and connected
2022-08-26 14:22:50,564 INFO    MainThread:12236 [wandb_init.py:init():596] updated telemetry
2022-08-26 14:22:50,565 INFO    MainThread:12236 [wandb_init.py:init():627] communicating run to backend with 30 second timeout
2022-08-26 14:22:52,818 ERROR   Thread-5  :12236 [retry.py:__call__():126] Retry attempt failed:
Traceback (most recent call last):
  File "C:\Python38\lib\site-packages\urllib3\connection.py", line 174, in _new_conn
    conn = connection.create_connection(
  File "C:\Python38\lib\site-packages\urllib3\util\connection.py", line 72, in create_connection
    for res in socket.getaddrinfo(host, port, family, socket.SOCK_STREAM):
  File "C:\Python38\lib\socket.py", line 918, in getaddrinfo
    for res in _socket.getaddrinfo(host, port, family, type, proto, flags):
socket.gaierror: [Errno 11001] getaddrinfo failed

During handling of the above exception, another exception occurred:

Traceback (most recent call last):
  File "C:\Python38\lib\site-packages\urllib3\connectionpool.py", line 703, in urlopen
    httplib_response = self._make_request(
  File "C:\Python38\lib\site-packages\urllib3\connectionpool.py", line 386, in _make_request
    self._validate_conn(conn)
  File "C:\Python38\lib\site-packages\urllib3\connectionpool.py", line 1040, in _validate_conn
    conn.connect()
  File "C:\Python38\lib\site-packages\urllib3\connection.py", line 358, in connect
    self.sock = conn = self._new_conn()
  File "C:\Python38\lib\site-packages\urllib3\connection.py", line 186, in _new_conn
    raise NewConnectionError(
urllib3.exceptions.NewConnectionError: <urllib3.connection.HTTPSConnection object at 0x000001FA43267160>: Failed to establish a new connection: [Errno 11001] getaddrinfo failed

During handling of the above exception, another exception occurred:

Traceback (most recent call last):
  File "C:\Python38\lib\site-packages\requests\adapters.py", line 489, in send
    resp = conn.urlopen(
  File "C:\Python38\lib\site-packages\urllib3\connectionpool.py", line 785, in urlopen
    retries = retries.increment(
  File "C:\Python38\lib\site-packages\urllib3\util\retry.py", line 592, in increment
    raise MaxRetryError(_pool, url, error or ResponseError(cause))
urllib3.exceptions.MaxRetryError: HTTPSConnectionPool(host='api.wandb.ai', port=443): Max retries exceeded with url: /graphql (Caused by NewConnectionError('<urllib3.connection.HTTPSConnection object at 0x000001FA43267160>: Failed to establish a new connection: [Errno 11001] getaddrinfo failed'))

During handling of the above exception, another exception occurred:

Traceback (most recent call last):
  File "C:\Python38\lib\site-packages\wandb\sdk\lib\retry.py", line 102, in __call__
    result = self._call_fn(*args, **kwargs)
  File "C:\Python38\lib\site-packages\wandb\sdk\internal\internal_api.py", line 140, in execute
    return self.client.execute(*args, **kwargs)
  File "C:\Python38\lib\site-packages\wandb\vendor\gql-0.2.0\wandb_gql\client.py", line 52, in execute
    result = self._get_result(document, *args, **kwargs)
  File "C:\Python38\lib\site-packages\wandb\vendor\gql-0.2.0\wandb_gql\client.py", line 60, in _get_result
    return self.transport.execute(document, *args, **kwargs)
  File "C:\Python38\lib\site-packages\wandb\vendor\gql-0.2.0\wandb_gql\transport\requests.py", line 38, in execute
    request = requests.post(self.url, **post_args)
  File "C:\Python38\lib\site-packages\requests\api.py", line 115, in post
    return request("post", url, data=data, json=json, **kwargs)
  File "C:\Python38\lib\site-packages\requests\api.py", line 59, in request
    return session.request(method=method, url=url, **kwargs)
  File "C:\Python38\lib\site-packages\requests\sessions.py", line 587, in request
    resp = self.send(prep, **send_kwargs)
  File "C:\Python38\lib\site-packages\requests\sessions.py", line 701, in send
    r = adapter.send(request, **kwargs)
  File "C:\Python38\lib\site-packages\requests\adapters.py", line 565, in send
    raise ConnectionError(e, request=request)
requests.exceptions.ConnectionError: HTTPSConnectionPool(host='api.wandb.ai', port=443): Max retries exceeded with url: /graphql (Caused by NewConnectionError('<urllib3.connection.HTTPSConnection object at 0x000001FA43267160>: Failed to establish a new connection: [Errno 11001] getaddrinfo failed'))
2022-08-26 14:23:20,580 INFO    MainThread:12236 [interface_shared.py:_communicate_run():326] couldn't get run from backend
2022-08-26 14:23:20,580 ERROR   MainThread:12236 [wandb_init.py:init():636] backend process timed out
2022-08-26 14:23:20,580 ERROR   MainThread:12236 [wandb_init.py:init():647] encountered error: Error communicating with wandb process
try: wandb.init(settings=wandb.Settings(start_method='fork'))
or:  wandb.init(settings=wandb.Settings(start_method='thread'))
For more info see: https://docs.wandb.ai/library/init#init-start-error
