2022-08-27 17:52:51,551 INFO    MainThread:5540 [internal.py:wandb_internal():90] W&B internal server running at pid: 5540, started at: 2022-08-27 17:52:51.547684
2022-08-27 17:52:51,552 INFO    WriterThread:5540 [datastore.py:open_for_write():75] open: D:\fp\ppo_rl\controllers\supervisor_manager\wandb\run-20220827_175250-1l9e6q42\run-1l9e6q42.wandb
2022-08-27 17:52:51,553 DEBUG   SenderThread:5540 [sender.py:send():235] send: header
2022-08-27 17:52:51,553 DEBUG   SenderThread:5540 [sender.py:send():235] send: run
2022-08-27 17:53:21,043 DEBUG   HandlerThread:5540 [handler.py:handle_request():141] handle_request: shutdown
2022-08-27 17:53:21,044 INFO    HandlerThread:5540 [handler.py:finish():806] shutting down handler
2022-08-27 17:53:21,772 INFO    WriterThread:5540 [datastore.py:close():279] close: D:\fp\ppo_rl\controllers\supervisor_manager\wandb\run-20220827_175250-1l9e6q42\run-1l9e6q42.wandb
2022-08-27 17:53:25,219 ERROR   SenderThread:5540 [retry.py:__call__():126] Retry attempt failed:
Traceback (most recent call last):
  File "C:\Python38\lib\site-packages\urllib3\connection.py", line 174, in _new_conn
    conn = connection.create_connection(
  File "C:\Python38\lib\site-packages\urllib3\util\connection.py", line 95, in create_connection
    raise err
  File "C:\Python38\lib\site-packages\urllib3\util\connection.py", line 85, in create_connection
    sock.connect(sa)
socket.timeout: timed out

During handling of the above exception, another exception occurred:

Traceback (most recent call last):
  File "C:\Python38\lib\site-packages\urllib3\connectionpool.py", line 703, in urlopen
    httplib_response = self._make_request(
  File "C:\Python38\lib\site-packages\urllib3\connectionpool.py", line 386, in _make_request
    self._validate_conn(conn)
  File "C:\Python38\lib\site-packages\urllib3\connectionpool.py", line 1040, in _validate_conn
    conn.connect()
  File "C:\Python38\lib\site-packages\urllib3\connection.py", line 358, in connect
    self.sock = conn = self._new_conn()
  File "C:\Python38\lib\site-packages\urllib3\connection.py", line 179, in _new_conn
    raise ConnectTimeoutError(
urllib3.exceptions.ConnectTimeoutError: (<urllib3.connection.HTTPSConnection object at 0x000001E2AE8C8610>, 'Connection to api.wandb.ai timed out. (connect timeout=10)')

During handling of the above exception, another exception occurred:

Traceback (most recent call last):
  File "C:\Python38\lib\site-packages\requests\adapters.py", line 489, in send
    resp = conn.urlopen(
  File "C:\Python38\lib\site-packages\urllib3\connectionpool.py", line 785, in urlopen
    retries = retries.increment(
  File "C:\Python38\lib\site-packages\urllib3\util\retry.py", line 592, in increment
    raise MaxRetryError(_pool, url, error or ResponseError(cause))
urllib3.exceptions.MaxRetryError: HTTPSConnectionPool(host='api.wandb.ai', port=443): Max retries exceeded with url: /graphql (Caused by ConnectTimeoutError(<urllib3.connection.HTTPSConnection object at 0x000001E2AE8C8610>, 'Connection to api.wandb.ai timed out. (connect timeout=10)'))

During handling of the above exception, another exception occurred:

Traceback (most recent call last):
  File "C:\Python38\lib\site-packages\wandb\sdk\lib\retry.py", line 102, in __call__
    result = self._call_fn(*args, **kwargs)
  File "C:\Python38\lib\site-packages\wandb\sdk\internal\internal_api.py", line 140, in execute
    return self.client.execute(*args, **kwargs)
  File "C:\Python38\lib\site-packages\wandb\vendor\gql-0.2.0\wandb_gql\client.py", line 52, in execute
    result = self._get_result(document, *args, **kwargs)
  File "C:\Python38\lib\site-packages\wandb\vendor\gql-0.2.0\wandb_gql\client.py", line 60, in _get_result
    return self.transport.execute(document, *args, **kwargs)
  File "C:\Python38\lib\site-packages\wandb\vendor\gql-0.2.0\wandb_gql\transport\requests.py", line 38, in execute
    request = requests.post(self.url, **post_args)
  File "C:\Python38\lib\site-packages\requests\api.py", line 115, in post
    return request("post", url, data=data, json=json, **kwargs)
  File "C:\Python38\lib\site-packages\requests\api.py", line 59, in request
    return session.request(method=method, url=url, **kwargs)
  File "C:\Python38\lib\site-packages\requests\sessions.py", line 587, in request
    resp = self.send(prep, **send_kwargs)
  File "C:\Python38\lib\site-packages\requests\sessions.py", line 701, in send
    r = adapter.send(request, **kwargs)
  File "C:\Python38\lib\site-packages\requests\adapters.py", line 553, in send
    raise ConnectTimeout(e, request=request)
requests.exceptions.ConnectTimeout: HTTPSConnectionPool(host='api.wandb.ai', port=443): Max retries exceeded with url: /graphql (Caused by ConnectTimeoutError(<urllib3.connection.HTTPSConnection object at 0x000001E2AE8C8610>, 'Connection to api.wandb.ai timed out. (connect timeout=10)'))
